2024-04-06 18:20:21,466 INFO    Thread-11 (_run_job):944 [wandb_setup.py:_flush():76] Current SDK version is 0.16.4
2024-04-06 18:20:21,467 INFO    Thread-11 (_run_job):944 [wandb_setup.py:_flush():76] Configure stats pid to 944
2024-04-06 18:20:21,467 INFO    Thread-11 (_run_job):944 [wandb_setup.py:_flush():76] Loading settings from /Users/pratikkadlak/.config/wandb/settings
2024-04-06 18:20:21,467 INFO    Thread-11 (_run_job):944 [wandb_setup.py:_flush():76] Loading settings from /Users/pratikkadlak/Pratik/DeepLearning/DL_Assignment_2/Convolution-Neural-Network/PartB/wandb/settings
2024-04-06 18:20:21,467 INFO    Thread-11 (_run_job):944 [wandb_setup.py:_flush():76] Loading settings from environment variables: {'project': 'DL_Assignment_2', 'entity': 'space_monkeys', 'root_dir': '/Users/pratikkadlak/Pratik/DeepLearning/DL_Assignment_2/Convolution-Neural-Network/PartB', 'run_id': '0yadui0c', 'sweep_param_path': '/Users/pratikkadlak/Pratik/DeepLearning/DL_Assignment_2/Convolution-Neural-Network/PartB/wandb/sweep-ufdkvxs5/config-0yadui0c.yaml', 'sweep_id': 'ufdkvxs5'}
2024-04-06 18:20:21,467 INFO    Thread-11 (_run_job):944 [wandb_setup.py:_flush():76] Applying setup settings: {'_disable_service': False}
2024-04-06 18:20:21,467 INFO    Thread-11 (_run_job):944 [wandb_setup.py:_flush():76] Inferring run settings from compute environment: {'program': '<python with no main file>'}
2024-04-06 18:20:21,467 INFO    Thread-11 (_run_job):944 [wandb_init.py:_log_setup():526] Logging user logs to /Users/pratikkadlak/Pratik/DeepLearning/DL_Assignment_2/Convolution-Neural-Network/PartB/wandb/run-20240406_182021-0yadui0c/logs/debug.log
2024-04-06 18:20:21,467 INFO    Thread-11 (_run_job):944 [wandb_init.py:_log_setup():527] Logging internal logs to /Users/pratikkadlak/Pratik/DeepLearning/DL_Assignment_2/Convolution-Neural-Network/PartB/wandb/run-20240406_182021-0yadui0c/logs/debug-internal.log
2024-04-06 18:20:21,467 INFO    Thread-11 (_run_job):944 [wandb_init.py:_jupyter_setup():472] configuring jupyter hooks <wandb.sdk.wandb_init._WandbInit object at 0x16e717450>
2024-04-06 18:20:21,468 INFO    Thread-11 (_run_job):944 [wandb_init.py:init():566] calling init triggers
2024-04-06 18:20:21,469 INFO    Thread-11 (_run_job):944 [wandb_init.py:init():573] wandb.init called with sweep_config: {'activation_func': 'ReLU', 'data_augment': 'Yes', 'dropout': 'Yes', 'epoch': 30, 'hidden_units': 512, 'optimizer': 'NAdam', 'prob': 0.2}
config: {}
2024-04-06 18:20:21,469 INFO    Thread-11 (_run_job):944 [wandb_init.py:init():616] starting backend
2024-04-06 18:20:21,469 INFO    Thread-11 (_run_job):944 [wandb_init.py:init():620] setting up manager
2024-04-06 18:20:21,475 INFO    Thread-11 (_run_job):944 [backend.py:_multiprocessing_setup():105] multiprocessing start_methods=spawn,fork,forkserver, using: spawn
2024-04-06 18:20:21,475 INFO    Thread-11 (_run_job):944 [wandb_init.py:init():628] backend started and connected
2024-04-06 18:20:21,488 INFO    Thread-11 (_run_job):944 [wandb_run.py:_config_callback():1343] config_cb None None {'activation_func': 'ReLU', 'data_augment': 'Yes', 'dropout': 'Yes', 'epoch': 30, 'hidden_units': 512, 'optimizer': 'NAdam', 'prob': 0.2}
2024-04-06 18:20:21,522 INFO    Thread-11 (_run_job):944 [wandb_run.py:_label_probe_notebook():1295] probe notebook
2024-04-06 18:20:21,522 INFO    Thread-11 (_run_job):944 [wandb_run.py:_label_probe_notebook():1305] Unable to probe notebook: 'NoneType' object has no attribute 'get'
2024-04-06 18:20:21,522 INFO    Thread-11 (_run_job):944 [wandb_init.py:init():720] updated telemetry
2024-04-06 18:20:21,550 INFO    Thread-11 (_run_job):944 [wandb_init.py:init():753] communicating run to backend with 90.0 second timeout
2024-04-06 18:20:22,274 INFO    Thread-11 (_run_job):944 [wandb_run.py:_on_init():2262] communicating current version
2024-04-06 18:20:22,384 INFO    Thread-11 (_run_job):944 [wandb_run.py:_on_init():2271] got version response upgrade_message: "wandb version 0.16.6 is available!  To upgrade, please run:\n $ pip install wandb --upgrade"

2024-04-06 18:20:22,384 INFO    Thread-11 (_run_job):944 [wandb_init.py:init():804] starting run threads in backend
2024-04-06 18:20:26,016 INFO    Thread-11 (_run_job):944 [wandb_run.py:_finish():1970] finishing run space_monkeys/DL_Assignment_2/0yadui0c
2024-04-06 18:20:26,016 INFO    Thread-11 (_run_job):944 [jupyter.py:save_history():445] not saving jupyter history
2024-04-06 18:20:26,016 INFO    Thread-11 (_run_job):944 [jupyter.py:save_ipynb():373] not saving jupyter notebook
2024-04-06 18:20:26,016 INFO    Thread-11 (_run_job):944 [wandb_init.py:_jupyter_teardown():454] cleaning up jupyter logic
2024-04-06 18:20:26,016 INFO    Thread-11 (_run_job):944 [wandb_run.py:_atexit_cleanup():2210] got exitcode: 0
2024-04-06 18:20:26,016 INFO    Thread-11 (_run_job):944 [wandb_run.py:_restore():2193] restore
2024-04-06 18:20:26,016 INFO    Thread-11 (_run_job):944 [wandb_run.py:_restore():2199] restore done
2024-04-06 18:20:28,026 ERROR   Thread-11 (_run_job):944 [ipython.py:update():120] Socket operation on non-socket
Traceback (most recent call last):
  File "/Users/pratikkadlak/anaconda3/lib/python3.11/site-packages/wandb/sdk/wandb_init.py", line 1176, in init
    run = wi.init()
          ^^^^^^^^^
  File "/Users/pratikkadlak/anaconda3/lib/python3.11/site-packages/wandb/sdk/wandb_init.py", line 846, in init
    run._on_start()
  File "/Users/pratikkadlak/anaconda3/lib/python3.11/site-packages/wandb/sdk/wandb_run.py", line 2280, in _on_start
    self._header(
  File "/Users/pratikkadlak/anaconda3/lib/python3.11/site-packages/wandb/sdk/wandb_run.py", line 3441, in _header
    Run._header_version_check_info(
  File "/Users/pratikkadlak/anaconda3/lib/python3.11/site-packages/wandb/sdk/wandb_run.py", line 3463, in _header_version_check_info
    printer.display(
  File "/Users/pratikkadlak/anaconda3/lib/python3.11/site-packages/wandb/sdk/lib/printer.py", line 68, in display
    self._display(text, level=level, default_text=default_text)
  File "/Users/pratikkadlak/anaconda3/lib/python3.11/site-packages/wandb/sdk/lib/printer.py", line 248, in _display
    self._display_fn_mapping(level)(text)
  File "/Users/pratikkadlak/anaconda3/lib/python3.11/site-packages/wandb/sdk/lib/ipython.py", line 81, in display_html
    return display(HTML(html))
           ^^^^^^^^^^^^^^^^^^^
  File "/Users/pratikkadlak/anaconda3/lib/python3.11/site-packages/IPython/core/display_functions.py", line 305, in display
    publish_display_data(data=format_dict, metadata=md_dict, **kwargs)
  File "/Users/pratikkadlak/anaconda3/lib/python3.11/site-packages/IPython/core/display_functions.py", line 93, in publish_display_data
    display_pub.publish(
  File "/Users/pratikkadlak/anaconda3/lib/python3.11/site-packages/wandb/sdk/wandb_init.py", line 483, in publish
    ipython.display_pub._orig_publish(data, metadata=metadata, **kwargs)
  File "/Users/pratikkadlak/anaconda3/lib/python3.11/site-packages/ipykernel/zmqshell.py", line 102, in publish
    self._flush_streams()
  File "/Users/pratikkadlak/anaconda3/lib/python3.11/site-packages/ipykernel/zmqshell.py", line 65, in _flush_streams
    sys.stdout.flush()
  File "/Users/pratikkadlak/anaconda3/lib/python3.11/site-packages/ipykernel/iostream.py", line 559, in flush
    self.pub_thread.schedule(self._flush)
  File "/Users/pratikkadlak/anaconda3/lib/python3.11/site-packages/ipykernel/iostream.py", line 251, in schedule
    self._event_pipe.send(b"")
  File "/Users/pratikkadlak/anaconda3/lib/python3.11/site-packages/zmq/sugar/socket.py", line 618, in send
    return super().send(data, flags=flags, copy=copy, track=track)
           ^^^^^^^^^^^^^^^^^^^^^^^^^^^^^^^^^^^^^^^^^^^^^^^^^^^^^^^
  File "zmq/backend/cython/socket.pyx", line 740, in zmq.backend.cython.socket.Socket.send
  File "zmq/backend/cython/socket.pyx", line 781, in zmq.backend.cython.socket.Socket.send
  File "zmq/backend/cython/socket.pyx", line 137, in zmq.backend.cython.socket._check_closed
zmq.error.ZMQError: Socket operation on non-socket

During handling of the above exception, another exception occurred:

Traceback (most recent call last):
  File "/Users/pratikkadlak/anaconda3/lib/python3.11/site-packages/wandb/sdk/wandb_init.py", line 1184, in init
    getcaller()
  File "/Users/pratikkadlak/anaconda3/lib/python3.11/site-packages/wandb/sdk/wandb_init.py", line 855, in getcaller
    print("Problem at:", src, line, func)
  File "/Users/pratikkadlak/anaconda3/lib/python3.11/site-packages/ipykernel/iostream.py", line 648, in write
    self._schedule_flush()
  File "/Users/pratikkadlak/anaconda3/lib/python3.11/site-packages/ipykernel/iostream.py", line 545, in _schedule_flush
    self.pub_thread.schedule(_schedule_in_thread)
  File "/Users/pratikkadlak/anaconda3/lib/python3.11/site-packages/ipykernel/iostream.py", line 251, in schedule
    self._event_pipe.send(b"")
  File "/Users/pratikkadlak/anaconda3/lib/python3.11/site-packages/zmq/sugar/socket.py", line 618, in send
    return super().send(data, flags=flags, copy=copy, track=track)
           ^^^^^^^^^^^^^^^^^^^^^^^^^^^^^^^^^^^^^^^^^^^^^^^^^^^^^^^
  File "zmq/backend/cython/socket.pyx", line 740, in zmq.backend.cython.socket.Socket.send
  File "zmq/backend/cython/socket.pyx", line 781, in zmq.backend.cython.socket.Socket.send
  File "zmq/backend/cython/socket.pyx", line 137, in zmq.backend.cython.socket._check_closed
zmq.error.ZMQError: Socket operation on non-socket

The above exception was the direct cause of the following exception:

Traceback (most recent call last):
  File "/Users/pratikkadlak/anaconda3/lib/python3.11/site-packages/wandb/agents/pyagent.py", line 308, in _run_job
    self._function()
  File "/var/folders/60/b9tm89f94198l_68mph00gyw0000gn/T/ipykernel_944/254422479.py", line 8, in train
    with wandb.init(project="DL_Assignment_2") as run:
         ^^^^^^^^^^^^^^^^^^^^^^^^^^^^^^^^^^^^^
  File "/Users/pratikkadlak/anaconda3/lib/python3.11/site-packages/wandb/sdk/wandb_init.py", line 1214, in init
    raise Error("An unexpected error occurred") from error_seen
wandb.errors.Error: An unexpected error occurred

During handling of the above exception, another exception occurred:

Traceback (most recent call last):
  File "/Users/pratikkadlak/anaconda3/lib/python3.11/site-packages/wandb/sdk/lib/ipython.py", line 113, in update
    self._progress.value = value
    ^^^^^^^^^^^^^^^^^^^^
  File "/Users/pratikkadlak/anaconda3/lib/python3.11/site-packages/traitlets/traitlets.py", line 729, in __set__
    self.set(obj, value)
  File "/Users/pratikkadlak/anaconda3/lib/python3.11/site-packages/traitlets/traitlets.py", line 718, in set
    obj._notify_trait(self.name, old_value, new_value)
  File "/Users/pratikkadlak/anaconda3/lib/python3.11/site-packages/traitlets/traitlets.py", line 1501, in _notify_trait
    self.notify_change(
  File "/Users/pratikkadlak/anaconda3/lib/python3.11/site-packages/ipywidgets/widgets/widget.py", line 693, in notify_change
    self.send_state(key=name)
  File "/Users/pratikkadlak/anaconda3/lib/python3.11/site-packages/ipywidgets/widgets/widget.py", line 579, in send_state
    self._send(msg, buffers=buffers)
  File "/Users/pratikkadlak/anaconda3/lib/python3.11/site-packages/ipywidgets/widgets/widget.py", line 818, in _send
    self.comm.send(data=msg, buffers=buffers)
  File "/Users/pratikkadlak/anaconda3/lib/python3.11/site-packages/comm/base_comm.py", line 113, in send
    self.publish_msg(
  File "/Users/pratikkadlak/anaconda3/lib/python3.11/site-packages/ipykernel/comm/comm.py", line 36, in publish_msg
    self.kernel.session.send(
  File "/Users/pratikkadlak/anaconda3/lib/python3.11/site-packages/jupyter_client/session.py", line 859, in send
    stream.send_multipart(to_send, copy=copy)
  File "/Users/pratikkadlak/anaconda3/lib/python3.11/site-packages/ipykernel/iostream.py", line 330, in send_multipart
    return self.io_thread.send_multipart(*args, **kwargs)
           ^^^^^^^^^^^^^^^^^^^^^^^^^^^^^^^^^^^^^^^^^^^^^^
  File "/Users/pratikkadlak/anaconda3/lib/python3.11/site-packages/ipykernel/iostream.py", line 260, in send_multipart
    self.schedule(lambda: self._really_send(*args, **kwargs))
  File "/Users/pratikkadlak/anaconda3/lib/python3.11/site-packages/ipykernel/iostream.py", line 251, in schedule
    self._event_pipe.send(b"")
  File "/Users/pratikkadlak/anaconda3/lib/python3.11/site-packages/zmq/sugar/socket.py", line 618, in send
    return super().send(data, flags=flags, copy=copy, track=track)
           ^^^^^^^^^^^^^^^^^^^^^^^^^^^^^^^^^^^^^^^^^^^^^^^^^^^^^^^
  File "zmq/backend/cython/socket.pyx", line 740, in zmq.backend.cython.socket.Socket.send
  File "zmq/backend/cython/socket.pyx", line 781, in zmq.backend.cython.socket.Socket.send
  File "zmq/backend/cython/socket.pyx", line 137, in zmq.backend.cython.socket._check_closed
zmq.error.ZMQError: Socket operation on non-socket
2024-04-06 18:20:28,061 INFO    Thread-11 (_run_job):944 [wandb_run.py:_restore():2193] restore
2024-04-06 18:20:28,061 INFO    Thread-11 (_run_job):944 [wandb_run.py:_restore():2199] restore done
2024-04-06 18:20:29,063 ERROR   Thread-11 (_run_job):944 [wandb_run.py:_atexit_cleanup():2231] Problem finishing run
Traceback (most recent call last):
  File "/Users/pratikkadlak/anaconda3/lib/python3.11/site-packages/wandb/sdk/wandb_init.py", line 1176, in init
    run = wi.init()
          ^^^^^^^^^
  File "/Users/pratikkadlak/anaconda3/lib/python3.11/site-packages/wandb/sdk/wandb_init.py", line 846, in init
    run._on_start()
  File "/Users/pratikkadlak/anaconda3/lib/python3.11/site-packages/wandb/sdk/wandb_run.py", line 2280, in _on_start
    self._header(
  File "/Users/pratikkadlak/anaconda3/lib/python3.11/site-packages/wandb/sdk/wandb_run.py", line 3441, in _header
    Run._header_version_check_info(
  File "/Users/pratikkadlak/anaconda3/lib/python3.11/site-packages/wandb/sdk/wandb_run.py", line 3463, in _header_version_check_info
    printer.display(
  File "/Users/pratikkadlak/anaconda3/lib/python3.11/site-packages/wandb/sdk/lib/printer.py", line 68, in display
    self._display(text, level=level, default_text=default_text)
  File "/Users/pratikkadlak/anaconda3/lib/python3.11/site-packages/wandb/sdk/lib/printer.py", line 248, in _display
    self._display_fn_mapping(level)(text)
  File "/Users/pratikkadlak/anaconda3/lib/python3.11/site-packages/wandb/sdk/lib/ipython.py", line 81, in display_html
    return display(HTML(html))
           ^^^^^^^^^^^^^^^^^^^
  File "/Users/pratikkadlak/anaconda3/lib/python3.11/site-packages/IPython/core/display_functions.py", line 305, in display
    publish_display_data(data=format_dict, metadata=md_dict, **kwargs)
  File "/Users/pratikkadlak/anaconda3/lib/python3.11/site-packages/IPython/core/display_functions.py", line 93, in publish_display_data
    display_pub.publish(
  File "/Users/pratikkadlak/anaconda3/lib/python3.11/site-packages/wandb/sdk/wandb_init.py", line 483, in publish
    ipython.display_pub._orig_publish(data, metadata=metadata, **kwargs)
  File "/Users/pratikkadlak/anaconda3/lib/python3.11/site-packages/ipykernel/zmqshell.py", line 102, in publish
    self._flush_streams()
  File "/Users/pratikkadlak/anaconda3/lib/python3.11/site-packages/ipykernel/zmqshell.py", line 65, in _flush_streams
    sys.stdout.flush()
  File "/Users/pratikkadlak/anaconda3/lib/python3.11/site-packages/ipykernel/iostream.py", line 559, in flush
    self.pub_thread.schedule(self._flush)
  File "/Users/pratikkadlak/anaconda3/lib/python3.11/site-packages/ipykernel/iostream.py", line 251, in schedule
    self._event_pipe.send(b"")
  File "/Users/pratikkadlak/anaconda3/lib/python3.11/site-packages/zmq/sugar/socket.py", line 618, in send
    return super().send(data, flags=flags, copy=copy, track=track)
           ^^^^^^^^^^^^^^^^^^^^^^^^^^^^^^^^^^^^^^^^^^^^^^^^^^^^^^^
  File "zmq/backend/cython/socket.pyx", line 740, in zmq.backend.cython.socket.Socket.send
  File "zmq/backend/cython/socket.pyx", line 781, in zmq.backend.cython.socket.Socket.send
  File "zmq/backend/cython/socket.pyx", line 137, in zmq.backend.cython.socket._check_closed
zmq.error.ZMQError: Socket operation on non-socket

During handling of the above exception, another exception occurred:

Traceback (most recent call last):
  File "/Users/pratikkadlak/anaconda3/lib/python3.11/site-packages/wandb/sdk/wandb_init.py", line 1184, in init
    getcaller()
  File "/Users/pratikkadlak/anaconda3/lib/python3.11/site-packages/wandb/sdk/wandb_init.py", line 855, in getcaller
    print("Problem at:", src, line, func)
  File "/Users/pratikkadlak/anaconda3/lib/python3.11/site-packages/ipykernel/iostream.py", line 648, in write
    self._schedule_flush()
  File "/Users/pratikkadlak/anaconda3/lib/python3.11/site-packages/ipykernel/iostream.py", line 545, in _schedule_flush
    self.pub_thread.schedule(_schedule_in_thread)
  File "/Users/pratikkadlak/anaconda3/lib/python3.11/site-packages/ipykernel/iostream.py", line 251, in schedule
    self._event_pipe.send(b"")
  File "/Users/pratikkadlak/anaconda3/lib/python3.11/site-packages/zmq/sugar/socket.py", line 618, in send
    return super().send(data, flags=flags, copy=copy, track=track)
           ^^^^^^^^^^^^^^^^^^^^^^^^^^^^^^^^^^^^^^^^^^^^^^^^^^^^^^^
  File "zmq/backend/cython/socket.pyx", line 740, in zmq.backend.cython.socket.Socket.send
  File "zmq/backend/cython/socket.pyx", line 781, in zmq.backend.cython.socket.Socket.send
  File "zmq/backend/cython/socket.pyx", line 137, in zmq.backend.cython.socket._check_closed
zmq.error.ZMQError: Socket operation on non-socket

The above exception was the direct cause of the following exception:

Traceback (most recent call last):
  File "/Users/pratikkadlak/anaconda3/lib/python3.11/site-packages/wandb/agents/pyagent.py", line 308, in _run_job
    self._function()
  File "/var/folders/60/b9tm89f94198l_68mph00gyw0000gn/T/ipykernel_944/254422479.py", line 8, in train
    with wandb.init(project="DL_Assignment_2") as run:
         ^^^^^^^^^^^^^^^^^^^^^^^^^^^^^^^^^^^^^
  File "/Users/pratikkadlak/anaconda3/lib/python3.11/site-packages/wandb/sdk/wandb_init.py", line 1214, in init
    raise Error("An unexpected error occurred") from error_seen
wandb.errors.Error: An unexpected error occurred

During handling of the above exception, another exception occurred:

Traceback (most recent call last):
  File "/Users/pratikkadlak/anaconda3/lib/python3.11/site-packages/wandb/sdk/lib/ipython.py", line 113, in update
    self._progress.value = value
    ^^^^^^^^^^^^^^^^^^^^
  File "/Users/pratikkadlak/anaconda3/lib/python3.11/site-packages/traitlets/traitlets.py", line 729, in __set__
    self.set(obj, value)
  File "/Users/pratikkadlak/anaconda3/lib/python3.11/site-packages/traitlets/traitlets.py", line 718, in set
    obj._notify_trait(self.name, old_value, new_value)
  File "/Users/pratikkadlak/anaconda3/lib/python3.11/site-packages/traitlets/traitlets.py", line 1501, in _notify_trait
    self.notify_change(
  File "/Users/pratikkadlak/anaconda3/lib/python3.11/site-packages/ipywidgets/widgets/widget.py", line 693, in notify_change
    self.send_state(key=name)
  File "/Users/pratikkadlak/anaconda3/lib/python3.11/site-packages/ipywidgets/widgets/widget.py", line 579, in send_state
    self._send(msg, buffers=buffers)
  File "/Users/pratikkadlak/anaconda3/lib/python3.11/site-packages/ipywidgets/widgets/widget.py", line 818, in _send
    self.comm.send(data=msg, buffers=buffers)
  File "/Users/pratikkadlak/anaconda3/lib/python3.11/site-packages/comm/base_comm.py", line 113, in send
    self.publish_msg(
  File "/Users/pratikkadlak/anaconda3/lib/python3.11/site-packages/ipykernel/comm/comm.py", line 36, in publish_msg
    self.kernel.session.send(
  File "/Users/pratikkadlak/anaconda3/lib/python3.11/site-packages/jupyter_client/session.py", line 859, in send
    stream.send_multipart(to_send, copy=copy)
  File "/Users/pratikkadlak/anaconda3/lib/python3.11/site-packages/ipykernel/iostream.py", line 330, in send_multipart
    return self.io_thread.send_multipart(*args, **kwargs)
           ^^^^^^^^^^^^^^^^^^^^^^^^^^^^^^^^^^^^^^^^^^^^^^
  File "/Users/pratikkadlak/anaconda3/lib/python3.11/site-packages/ipykernel/iostream.py", line 260, in send_multipart
    self.schedule(lambda: self._really_send(*args, **kwargs))
  File "/Users/pratikkadlak/anaconda3/lib/python3.11/site-packages/ipykernel/iostream.py", line 251, in schedule
    self._event_pipe.send(b"")
  File "/Users/pratikkadlak/anaconda3/lib/python3.11/site-packages/zmq/sugar/socket.py", line 618, in send
    return super().send(data, flags=flags, copy=copy, track=track)
           ^^^^^^^^^^^^^^^^^^^^^^^^^^^^^^^^^^^^^^^^^^^^^^^^^^^^^^^
  File "zmq/backend/cython/socket.pyx", line 740, in zmq.backend.cython.socket.Socket.send
  File "zmq/backend/cython/socket.pyx", line 781, in zmq.backend.cython.socket.Socket.send
  File "zmq/backend/cython/socket.pyx", line 137, in zmq.backend.cython.socket._check_closed
zmq.error.ZMQError: Socket operation on non-socket

During handling of the above exception, another exception occurred:

Traceback (most recent call last):
  File "/Users/pratikkadlak/anaconda3/lib/python3.11/site-packages/wandb/sdk/wandb_run.py", line 2219, in _atexit_cleanup
    self._on_finish()
  File "/Users/pratikkadlak/anaconda3/lib/python3.11/site-packages/wandb/sdk/wandb_run.py", line 2466, in _on_finish
    _ = exit_handle.wait(timeout=-1, on_progress=self._on_progress_exit)
        ^^^^^^^^^^^^^^^^^^^^^^^^^^^^^^^^^^^^^^^^^^^^^^^^^^^^^^^^^^^^^^^^
  File "/Users/pratikkadlak/anaconda3/lib/python3.11/site-packages/wandb/sdk/lib/mailbox.py", line 303, in wait
    on_progress(progress_handle)
  File "/Users/pratikkadlak/anaconda3/lib/python3.11/site-packages/wandb/sdk/wandb_run.py", line 2445, in _on_progress_exit
    self._footer_file_pusher_status_info(
  File "/Users/pratikkadlak/anaconda3/lib/python3.11/site-packages/wandb/sdk/wandb_run.py", line 3662, in _footer_file_pusher_status_info
    Run._footer_single_run_file_pusher_status_info(
  File "/Users/pratikkadlak/anaconda3/lib/python3.11/site-packages/wandb/sdk/wandb_run.py", line 3713, in _footer_single_run_file_pusher_status_info
    printer.progress_update(line, percent_done)
  File "/Users/pratikkadlak/anaconda3/lib/python3.11/site-packages/wandb/sdk/lib/printer.py", line 288, in progress_update
    self._progress.update(percent_done, text)
  File "/Users/pratikkadlak/anaconda3/lib/python3.11/site-packages/wandb/sdk/lib/ipython.py", line 121, in update
    wandb.termwarn(
  File "/Users/pratikkadlak/anaconda3/lib/python3.11/site-packages/wandb/errors/term.py", line 50, in termwarn
    _log(
  File "/Users/pratikkadlak/anaconda3/lib/python3.11/site-packages/wandb/errors/term.py", line 95, in _log
    click.echo(line, file=sys.stderr, nl=newline)
  File "/Users/pratikkadlak/anaconda3/lib/python3.11/site-packages/click/utils.py", line 299, in echo
    file.flush()
  File "/Users/pratikkadlak/anaconda3/lib/python3.11/site-packages/ipykernel/iostream.py", line 559, in flush
    self.pub_thread.schedule(self._flush)
  File "/Users/pratikkadlak/anaconda3/lib/python3.11/site-packages/ipykernel/iostream.py", line 251, in schedule
    self._event_pipe.send(b"")
  File "/Users/pratikkadlak/anaconda3/lib/python3.11/site-packages/zmq/sugar/socket.py", line 618, in send
    return super().send(data, flags=flags, copy=copy, track=track)
           ^^^^^^^^^^^^^^^^^^^^^^^^^^^^^^^^^^^^^^^^^^^^^^^^^^^^^^^
  File "zmq/backend/cython/socket.pyx", line 740, in zmq.backend.cython.socket.Socket.send
  File "zmq/backend/cython/socket.pyx", line 781, in zmq.backend.cython.socket.Socket.send
  File "zmq/backend/cython/socket.pyx", line 137, in zmq.backend.cython.socket._check_closed
zmq.error.ZMQError: Socket operation on non-socket
2024-04-06 18:21:54,216 INFO    MainThread:944 [pyagent.py:run():324] Starting sweep agent: entity=None, project=None, count=50
2024-04-06 18:22:39,069 INFO    MainThread:944 [wandb_run.py:_finish():1970] finishing run space_monkeys/DL_Assignment_2/0yadui0c
2024-04-06 18:22:39,070 INFO    MainThread:944 [jupyter.py:save_history():445] not saving jupyter history
2024-04-06 18:22:39,070 INFO    MainThread:944 [jupyter.py:save_ipynb():373] not saving jupyter notebook
2024-04-06 18:22:39,070 INFO    MainThread:944 [wandb_init.py:_jupyter_teardown():454] cleaning up jupyter logic
2024-04-06 18:30:04,502 INFO    MainThread:944 [pyagent.py:run():324] Starting sweep agent: entity=None, project=None, count=50
2024-04-06 18:31:32,167 INFO    MainThread:944 [wandb_run.py:_finish():1970] finishing run space_monkeys/DL_Assignment_2/0yadui0c
2024-04-06 18:31:32,169 INFO    MainThread:944 [jupyter.py:save_history():445] not saving jupyter history
2024-04-06 18:31:32,169 INFO    MainThread:944 [jupyter.py:save_ipynb():373] not saving jupyter notebook
2024-04-06 18:31:32,169 INFO    MainThread:944 [wandb_init.py:_jupyter_teardown():454] cleaning up jupyter logic
